<?xml version="1.0" encoding="UTF-8"?>
<!-- Generated by org.testng.reporters.JUnitXMLReporter -->
<testsuite hostname="ETOLBANOS" name="Default test" tests="1" failures="1" timestamp="10 Jun 2014 17:51:01 GMT" time="21.219" errors="0">
  <testcase name="@AfterTest tearDown" time="0.0" classname="mySQLTest.ConnectDB">
    <failure type="java.lang.NullPointerException">
      <![CDATA[java.lang.NullPointerException
	at mySQLTest.ConnectDB.tearDown(ConnectDB.java:68)
	at sun.reflect.NativeMethodAccessorImpl.invoke0(Native Method)
	at sun.reflect.NativeMethodAccessorImpl.invoke(Unknown Source)
	at sun.reflect.DelegatingMethodAccessorImpl.invoke(Unknown Source)
	at java.lang.reflect.Method.invoke(Unknown Source)
	at org.testng.internal.MethodInvocationHelper.invokeMethod(MethodInvocationHelper.java:84)
	at org.testng.internal.Invoker.invokeConfigurationMethod(Invoker.java:564)
	at org.testng.internal.Invoker.invokeConfigurations(Invoker.java:213)
	at org.testng.internal.Invoker.invokeConfigurations(Invoker.java:138)
	at org.testng.TestRunner.afterRun(TestRunner.java:1014)
	at org.testng.TestRunner.run(TestRunner.java:621)
	at org.testng.SuiteRunner.runTest(SuiteRunner.java:334)
	at org.testng.SuiteRunner.runSequentially(SuiteRunner.java:329)
	at org.testng.SuiteRunner.privateRun(SuiteRunner.java:291)
	at org.testng.SuiteRunner.run(SuiteRunner.java:240)
	at org.testng.SuiteRunnerWorker.runSuite(SuiteRunnerWorker.java:52)
	at org.testng.SuiteRunnerWorker.run(SuiteRunnerWorker.java:86)
	at org.testng.TestNG.runSuitesSequentially(TestNG.java:1224)
	at org.testng.TestNG.runSuitesLocally(TestNG.java:1149)
	at org.testng.TestNG.run(TestNG.java:1057)
	at org.testng.remote.RemoteTestNG.run(RemoteTestNG.java:111)
	at org.testng.remote.RemoteTestNG.initAndRun(RemoteTestNG.java:204)
	at org.testng.remote.RemoteTestNG.main(RemoteTestNG.java:175)
]]>
    </failure>
  </testcase> <!-- @AfterTest tearDown -->
  <testcase name="CreateDB" time="21.183" classname="mySQLTest.ConnectDB">
    <failure type="com.mysql.jdbc.exceptions.jdbc4.CommunicationsException" message="Communications link failure

The last packet sent successfully to the server was 0 milliseconds ago. The driver has not received any packets from the server.">
      <![CDATA[com.mysql.jdbc.exceptions.jdbc4.CommunicationsException: Communications link failure

The last packet sent successfully to the server was 0 milliseconds ago. The driver has not received any packets from the server.
	at sun.reflect.NativeConstructorAccessorImpl.newInstance0(Native Method)
	at sun.reflect.NativeConstructorAccessorImpl.newInstance(Unknown Source)
	at sun.reflect.DelegatingConstructorAccessorImpl.newInstance(Unknown Source)
	at java.lang.reflect.Constructor.newInstance(Unknown Source)
	at com.mysql.jdbc.Util.handleNewInstance(Util.java:411)
	at com.mysql.jdbc.SQLError.createCommunicationsException(SQLError.java:1117)
	at com.mysql.jdbc.MysqlIO.<init>(MysqlIO.java:350)
	at com.mysql.jdbc.ConnectionImpl.coreConnect(ConnectionImpl.java:2408)
	at com.mysql.jdbc.ConnectionImpl.connectOneTryOnly(ConnectionImpl.java:2445)
	at com.mysql.jdbc.ConnectionImpl.createNewIO(ConnectionImpl.java:2230)
	at com.mysql.jdbc.ConnectionImpl.<init>(ConnectionImpl.java:813)
	at com.mysql.jdbc.JDBC4Connection.<init>(JDBC4Connection.java:47)
	at sun.reflect.NativeConstructorAccessorImpl.newInstance0(Native Method)
	at sun.reflect.NativeConstructorAccessorImpl.newInstance(Unknown Source)
	at sun.reflect.DelegatingConstructorAccessorImpl.newInstance(Unknown Source)
	at java.lang.reflect.Constructor.newInstance(Unknown Source)
	at com.mysql.jdbc.Util.handleNewInstance(Util.java:411)
	at com.mysql.jdbc.ConnectionImpl.getInstance(ConnectionImpl.java:399)
	at com.mysql.jdbc.NonRegisteringDriver.connect(NonRegisteringDriver.java:334)
	at java.sql.DriverManager.getConnection(Unknown Source)
	at java.sql.DriverManager.getConnection(Unknown Source)
	at mySQLTest.ConnectDB.CreateDB(ConnectDB.java:44)
	at sun.reflect.NativeMethodAccessorImpl.invoke0(Native Method)
	at sun.reflect.NativeMethodAccessorImpl.invoke(Unknown Source)
	at sun.reflect.DelegatingMethodAccessorImpl.invoke(Unknown Source)
	at java.lang.reflect.Method.invoke(Unknown Source)
	at org.testng.internal.MethodInvocationHelper.invokeMethod(MethodInvocationHelper.java:84)
	at org.testng.internal.Invoker.invokeMethod(Invoker.java:714)
	at org.testng.internal.Invoker.invokeTestMethod(Invoker.java:901)
	at org.testng.internal.Invoker.invokeTestMethods(Invoker.java:1231)
	at org.testng.internal.TestMethodWorker.invokeTestMethods(TestMethodWorker.java:127)
	at org.testng.internal.TestMethodWorker.run(TestMethodWorker.java:111)
	at org.testng.TestRunner.privateRun(TestRunner.java:767)
	at org.testng.TestRunner.run(TestRunner.java:617)
	at org.testng.SuiteRunner.runTest(SuiteRunner.java:334)
	at org.testng.SuiteRunner.runSequentially(SuiteRunner.java:329)
	at org.testng.SuiteRunner.privateRun(SuiteRunner.java:291)
	at org.testng.SuiteRunner.run(SuiteRunner.java:240)
	at org.testng.SuiteRunnerWorker.runSuite(SuiteRunnerWorker.java:52)
	at org.testng.SuiteRunnerWorker.run(SuiteRunnerWorker.java:86)
	at org.testng.TestNG.runSuitesSequentially(TestNG.java:1224)
	at org.testng.TestNG.runSuitesLocally(TestNG.java:1149)
	at org.testng.TestNG.run(TestNG.java:1057)
	at org.testng.remote.RemoteTestNG.run(RemoteTestNG.java:111)
	at org.testng.remote.RemoteTestNG.initAndRun(RemoteTestNG.java:204)
	at org.testng.remote.RemoteTestNG.main(RemoteTestNG.java:175)
Caused by: java.net.ConnectException: Connection timed out: connect
	at java.net.DualStackPlainSocketImpl.connect0(Native Method)
	at java.net.DualStackPlainSocketImpl.socketConnect(Unknown Source)
	at java.net.AbstractPlainSocketImpl.doConnect(Unknown Source)
	at java.net.AbstractPlainSocketImpl.connectToAddress(Unknown Source)
	at java.net.AbstractPlainSocketImpl.connect(Unknown Source)
	at java.net.PlainSocketImpl.connect(Unknown Source)
	at java.net.SocksSocketImpl.connect(Unknown Source)
	at java.net.Socket.connect(Unknown Source)
	at java.net.Socket.connect(Unknown Source)
	at java.net.Socket.<init>(Unknown Source)
	at java.net.Socket.<init>(Unknown Source)
	at com.mysql.jdbc.StandardSocketFactory.connect(StandardSocketFactory.java:259)
	at com.mysql.jdbc.MysqlIO.<init>(MysqlIO.java:300)
	... 39 more
]]>
    </failure>
  </testcase> <!-- CreateDB -->
</testsuite> <!-- Default test -->
